Workbook

Sheet Summary
A1: TRINITY PRESBYTERIAN SCHOOL
A2: Five-Year Financial Forecast - Summary by Major Category
A3: ="Data check: "&B46 -> Data check: OK - ties to QuickBooks
A5: Fiscal year ending June 30 | B5: =Inputs!C$4 -> FY27 | C5: =Inputs!D$4 -> FY28 | D5: =Inputs!E$4 -> FY29 | E5: =Inputs!F$4 -> FY30 | F5: =Inputs!G$4 -> FY31 | G5: 5-yr CAGR
A6: Enrollment (students) | B6: =Enrollment!B21 -> 582 | C6: =Enrollment!C21 -> 591 | D6: =Enrollment!D21 -> 588 | E6: =Enrollment!E21 -> 583 | F6: =Enrollment!F21 -> 579
A7: Tuition rate increase | B7: =Inputs!C9 -> 0.04 | C7: =Inputs!D9 -> 0.05 | D7: =Inputs!E9 -> 0.045 | E7: =Inputs!F9 -> 0.045 | F7: =Inputs!G9 -> 0.04
A8: Salary increase | B8: =Inputs!C10 -> 0.025 | C8: =Inputs!D10 -> 0.03 | D8: =Inputs!E10 -> 0.03 | E8: =Inputs!F10 -> 0.03 | F8: =Inputs!G10 -> 0.03
A10: REVENUE
A11: 1 Tuition and Fees | B11: =SUMIFS('Forecast Detail'!G$8:G$400,'Forecast Detail'!$B$8:$B$400,$A11)+SUMIFS('QB Import'!$B$1:$B$600,'QB Import'!$F$1:$F$600,$A11,'QB Import'!$I$1:$I$600,"UNMAPPED") -> 8799382 | C11: =SUMIFS('Forecast Detail'!H$8:H$400,'Forecast Detail'!$B$8:$B$400,$A11)+SUMIFS('QB Import'!$B$1:$B$600,'QB Import'!$F$1:$F$600,$A11,'QB Import'!$I$1:$I$600,"UNMAPPED") -> 9300918.4 | D11: =SUMIFS('Forecast Detail'!I$8:I$400,'Forecast Detail'!$B$8:$B$400,$A11)+SUMIFS('QB Import'!$B$1:$B$600,'QB Import'!$F$1:$F$600,$A11,'QB Import'!$I$1:$I$600,"UNMAPPED") -> 9629546.3 | E11: =SUMIFS('Forecast Detail'!J$8:J$400,'Forecast Detail'!$B$8:$B$400,$A11)+SUMIFS('QB Import'!$B$1:$B$600,'QB Import'!$F$1:$F$600,$A11,'QB Import'!$I$1:$I$600,"UNMAPPED") -> 9941469.6 | F11: =SUMIFS('Forecast Detail'!K$8:K$400,'Forecast Detail'!$B$8:$B$400,$A11)+SUMIFS('QB Import'!$B$1:$B$600,'QB Import'!$F$1:$F$600,$A11,'QB Import'!$I$1:$I$600,"UNMAPPED") -> 10246937 | G11: =IF(AND(B11>0,F11>0),(F11/B11)^(1/4)-1,"") -> 0.038808452
A12: 2 Interest and Other Income | B12: =SUMIFS('Forecast Detail'!G$8:G$400,'Forecast Detail'!$B$8:$B$400,$A12)+SUMIFS('QB Import'!$B$1:$B$600,'QB Import'!$F$1:$F$600,$A12,'QB Import'!$I$1:$I$600,"UNMAPPED") -> 445000 | C12: =SUMIFS('Forecast Detail'!H$8:H$400,'Forecast Detail'!$B$8:$B$400,$A12)+SUMIFS('QB Import'!$B$1:$B$600,'QB Import'!$F$1:$F$600,$A12,'QB Import'!$I$1:$I$600,"UNMAPPED") -> 394005.03 | D12: =SUMIFS('Forecast Detail'!I$8:I$400,'Forecast Detail'!$B$8:$B$400,$A12)+SUMIFS('QB Import'!$B$1:$B$600,'QB Import'!$F$1:$F$600,$A12,'QB Import'!$I$1:$I$600,"UNMAPPED") -> 344005.03 | E12: =SUMIFS('Forecast Detail'!J$8:J$400,'Forecast Detail'!$B$8:$B$400,$A12)+SUMIFS('QB Import'!$B$1:$B$600,'QB Import'!$F$1:$F$600,$A12,'QB Import'!$I$1:$I$600,"UNMAPPED") -> 344005.03 | F12: =SUMIFS('Forecast Detail'!K$8:K$400,'Forecast Detail'!$B$8:$B$400,$A12)+SUMIFS('QB Import'!$B$1:$B$600,'QB Import'!$F$1:$F$600,$A12,'QB Import'!$I$1:$I$600,"UNMAPPED") -> 344005.03 | G12: =IF(AND(B12>0,F12>0),(F12/B12)^(1/4)-1,"") -> -0.062327464
A13: 4 Other Miscellaneous Income | B13: =SUMIFS('Forecast Detail'!G$8:G$400,'Forecast Detail'!$B$8:$B$400,$A13)+SUMIFS('QB Import'!$B$1:$B$600,'QB Import'!$F$1:$F$600,$A13,'QB Import'!$I$1:$I$600,"UNMAPPED") -> 60000 | C13: =SUMIFS('Forecast Detail'!H$8:H$400,'Forecast Detail'!$B$8:$B$400,$A13)+SUMIFS('QB Import'!$B$1:$B$600,'QB Import'!$F$1:$F$600,$A13,'QB Import'!$I$1:$I$600,"UNMAPPED") -> 60000 | D13: =SUMIFS('Forecast Detail'!I$8:I$400,'Forecast Detail'!$B$8:$B$400,$A13)+SUMIFS('QB Import'!$B$1:$B$600,'QB Import'!$F$1:$F$600,$A13,'QB Import'!$I$1:$I$600,"UNMAPPED") -> 60000 | E13: =SUMIFS('Forecast Detail'!J$8:J$400,'Forecast Detail'!$B$8:$B$400,$A13)+SUMIFS('QB Import'!$B$1:$B$600,'QB Import'!$F$1:$F$600,$A13,'QB Import'!$I$1:$I$600,"UNMAPPED") -> 60000 | F13: =SUMIFS('Forecast Detail'!K$8:K$400,'Forecast Detail'!$B$8:$B$400,$A13)+SUMIFS('QB Import'!$B$1:$B$600,'QB Import'!$F$1:$F$600,$A13,'QB Import'!$I$1:$I$600,"UNMAPPED") -> 60000 | G13: =IF(AND(B13>0,F13>0),(F13/B13)^(1/4)-1,"") -> 0
A14: 5 Athletic Income | B14: =SUMIFS('Forecast Detail'!G$8:G$400,'Forecast Detail'!$B$8:$B$400,$A14)+SUMIFS('QB Import'!$B$1:$B$600,'QB Import'!$F$1:$F$600,$A14,'QB Import'!$I$1:$I$600,"UNMAPPED") -> 0 | C14: =SUMIFS('Forecast Detail'!H$8:H$400,'Forecast Detail'!$B$8:$B$400,$A14)+SUMIFS('QB Import'!$B$1:$B$600,'QB Import'!$F$1:$F$600,$A14,'QB Import'!$I$1:$I$600,"UNMAPPED") -> 0 | D14: =SUMIFS('Forecast Detail'!I$8:I$400,'Forecast Detail'!$B$8:$B$400,$A14)+SUMIFS('QB Import'!$B$1:$B$600,'QB Import'!$F$1:$F$600,$A14,'QB Import'!$I$1:$I$600,"UNMAPPED") -> 0 | E14: =SUMIFS('Forecast Detail'!J$8:J$400,'Forecast Detail'!$B$8:$B$400,$A14)+SUMIFS('QB Import'!$B$1:$B$600,'QB Import'!$F$1:$F$600,$A14,'QB Import'!$I$1:$I$600,"UNMAPPED") -> 0 | F14: =SUMIFS('Forecast Detail'!K$8:K$400,'Forecast Detail'!$B$8:$B$400,$A14)+SUMIFS('QB Import'!$B$1:$B$600,'QB Import'!$F$1:$F$600,$A14,'QB Import'!$I$1:$I$600,"UNMAPPED") -> 0 | G14: =IF(AND(B14>0,F14>0),(F14/B14)^(1/4)-1,"")
A15: Total Revenue | B15: =SUM(B11:B14) -> 9304382 | C15: =SUM(C11:C14) -> 9754923.5 | D15: =SUM(D11:D14) -> 10033551 | E15: =SUM(E11:E14) -> 10345475 | F15: =SUM(F11:F14) -> 10650942 | G15: =IF(AND(B15>0,F15>0),(F15/B15)^(1/4)-1,"") -> 0.034368111
A17: EXPENSES
A18: 1 Salaries and Benefits | B18: =SUMIFS('Forecast Detail'!G$8:G$400,'Forecast Detail'!$B$8:$B$400,$A18)+SUMIFS('QB Import'!$B$1:$B$600,'QB Import'!$F$1:$F$600,$A18,'QB Import'!$I$1:$I$600,"UNMAPPED") -> 6253109 | C18: =SUMIFS('Forecast Detail'!H$8:H$400,'Forecast Detail'!$B$8:$B$400,$A18)+SUMIFS('QB Import'!$B$1:$B$600,'QB Import'!$F$1:$F$600,$A18,'QB Import'!$I$1:$I$600,"UNMAPPED") -> 6455524.8 | D18: =SUMIFS('Forecast Detail'!I$8:I$400,'Forecast Detail'!$B$8:$B$400,$A18)+SUMIFS('QB Import'!$B$1:$B$600,'QB Import'!$F$1:$F$600,$A18,'QB Import'!$I$1:$I$600,"UNMAPPED") -> 6653066.2 | E18: =SUMIFS('Forecast Detail'!J$8:J$400,'Forecast Detail'!$B$8:$B$400,$A18)+SUMIFS('QB Import'!$B$1:$B$600,'QB Import'!$F$1:$F$600,$A18,'QB Import'!$I$1:$I$600,"UNMAPPED") -> 6854595.5 | F18: =SUMIFS('Forecast Detail'!K$8:K$400,'Forecast Detail'!$B$8:$B$400,$A18)+SUMIFS('QB Import'!$B$1:$B$600,'QB Import'!$F$1:$F$600,$A18,'QB Import'!$I$1:$I$600,"UNMAPPED") -> 7061481.9 | G18: =IF(AND(B18>0,F18>0),(F18/B18)^(1/4)-1,"") -> 0.030860652
A19: 2 Instructional Expenses | B19: =SUMIFS('Forecast Detail'!G$8:G$400,'Forecast Detail'!$B$8:$B$400,$A19)+SUMIFS('QB Import'!$B$1:$B$600,'QB Import'!$F$1:$F$600,$A19,'QB Import'!$I$1:$I$600,"UNMAPPED") -> 252750 | C19: =SUMIFS('Forecast Detail'!H$8:H$400,'Forecast Detail'!$B$8:$B$400,$A19)+SUMIFS('QB Import'!$B$1:$B$600,'QB Import'!$F$1:$F$600,$A19,'QB Import'!$I$1:$I$600,"UNMAPPED") -> 260332.5 | D19: =SUMIFS('Forecast Detail'!I$8:I$400,'Forecast Detail'!$B$8:$B$400,$A19)+SUMIFS('QB Import'!$B$1:$B$600,'QB Import'!$F$1:$F$600,$A19,'QB Import'!$I$1:$I$600,"UNMAPPED") -> 268142.47 | E19: =SUMIFS('Forecast Detail'!J$8:J$400,'Forecast Detail'!$B$8:$B$400,$A19)+SUMIFS('QB Import'!$B$1:$B$600,'QB Import'!$F$1:$F$600,$A19,'QB Import'!$I$1:$I$600,"UNMAPPED") -> 276186.75 | F19: =SUMIFS('Forecast Detail'!K$8:K$400,'Forecast Detail'!$B$8:$B$400,$A19)+SUMIFS('QB Import'!$B$1:$B$600,'QB Import'!$F$1:$F$600,$A19,'QB Import'!$I$1:$I$600,"UNMAPPED") -> 284472.35 | G19: =IF(AND(B19>0,F19>0),(F19/B19)^(1/4)-1,"") -> 0.03
A20: 3 Operations | B20: =SUMIFS('Forecast Detail'!G$8:G$400,'Forecast Detail'!$B$8:$B$400,$A20)+SUMIFS('QB Import'!$B$1:$B$600,'QB Import'!$F$1:$F$600,$A20,'QB Import'!$I$1:$I$600,"UNMAPPED") -> 1847250 | C20: =SUMIFS('Forecast Detail'!H$8:H$400,'Forecast Detail'!$B$8:$B$400,$A20)+SUMIFS('QB Import'!$B$1:$B$600,'QB Import'!$F$1:$F$600,$A20,'QB Import'!$I$1:$I$600,"UNMAPPED") -> 1914294.8 | D20: =SUMIFS('Forecast Detail'!I$8:I$400,'Forecast Detail'!$B$8:$B$400,$A20)+SUMIFS('QB Import'!$B$1:$B$600,'QB Import'!$F$1:$F$600,$A20,'QB Import'!$I$1:$I$600,"UNMAPPED") -> 1967731.6 | E20: =SUMIFS('Forecast Detail'!J$8:J$400,'Forecast Detail'!$B$8:$B$400,$A20)+SUMIFS('QB Import'!$B$1:$B$600,'QB Import'!$F$1:$F$600,$A20,'QB Import'!$I$1:$I$600,"UNMAPPED") -> 2019910.6 | F20: =SUMIFS('Forecast Detail'!K$8:K$400,'Forecast Detail'!$B$8:$B$400,$A20)+SUMIFS('QB Import'!$B$1:$B$600,'QB Import'!$F$1:$F$600,$A20,'QB Import'!$I$1:$I$600,"UNMAPPED") -> 2074861 | G20: =IF(AND(B20>0,F20>0),(F20/B20)^(1/4)-1,"") -> 0.029475066
A21: 4 Administrative | B21: =SUMIFS('Forecast Detail'!G$8:G$400,'Forecast Detail'!$B$8:$B$400,$A21)+SUMIFS('QB Import'!$B$1:$B$600,'QB Import'!$F$1:$F$600,$A21,'QB Import'!$I$1:$I$600,"UNMAPPED") -> 778368 | C21: =SUMIFS('Forecast Detail'!H$8:H$400,'Forecast Detail'!$B$8:$B$400,$A21)+SUMIFS('QB Import'!$B$1:$B$600,'QB Import'!$F$1:$F$600,$A21,'QB Import'!$I$1:$I$600,"UNMAPPED") -> 795138.74 | D21: =SUMIFS('Forecast Detail'!I$8:I$400,'Forecast Detail'!$B$8:$B$400,$A21)+SUMIFS('QB Import'!$B$1:$B$600,'QB Import'!$F$1:$F$600,$A21,'QB Import'!$I$1:$I$600,"UNMAPPED") -> 810947.37 | E21: =SUMIFS('Forecast Detail'!J$8:J$400,'Forecast Detail'!$B$8:$B$400,$A21)+SUMIFS('QB Import'!$B$1:$B$600,'QB Import'!$F$1:$F$600,$A21,'QB Import'!$I$1:$I$600,"UNMAPPED") -> 703223.52 | F21: =SUMIFS('Forecast Detail'!K$8:K$400,'Forecast Detail'!$B$8:$B$400,$A21)+SUMIFS('QB Import'!$B$1:$B$600,'QB Import'!$F$1:$F$600,$A21,'QB Import'!$I$1:$I$600,"UNMAPPED") -> 658007.96 | G21: =IF(AND(B21>0,F21>0),(F21/B21)^(1/4)-1,"") -> -0.041125998
A22: 5 Athletic Expenses | B22: =SUMIFS('Forecast Detail'!G$8:G$400,'Forecast Detail'!$B$8:$B$400,$A22)+SUMIFS('QB Import'!$B$1:$B$600,'QB Import'!$F$1:$F$600,$A22,'QB Import'!$I$1:$I$600,"UNMAPPED") -> 171263 | C22: =SUMIFS('Forecast Detail'!H$8:H$400,'Forecast Detail'!$B$8:$B$400,$A22)+SUMIFS('QB Import'!$B$1:$B$600,'QB Import'!$F$1:$F$600,$A22,'QB Import'!$I$1:$I$600,"UNMAPPED") -> 176400.89 | D22: =SUMIFS('Forecast Detail'!I$8:I$400,'Forecast Detail'!$B$8:$B$400,$A22)+SUMIFS('QB Import'!$B$1:$B$600,'QB Import'!$F$1:$F$600,$A22,'QB Import'!$I$1:$I$600,"UNMAPPED") -> 181692.92 | E22: =SUMIFS('Forecast Detail'!J$8:J$400,'Forecast Detail'!$B$8:$B$400,$A22)+SUMIFS('QB Import'!$B$1:$B$600,'QB Import'!$F$1:$F$600,$A22,'QB Import'!$I$1:$I$600,"UNMAPPED") -> 187143.7 | F22: =SUMIFS('Forecast Detail'!K$8:K$400,'Forecast Detail'!$B$8:$B$400,$A22)+SUMIFS('QB Import'!$B$1:$B$600,'QB Import'!$F$1:$F$600,$A22,'QB Import'!$I$1:$I$600,"UNMAPPED") -> 192758.02 | G22: =IF(AND(B22>0,F22>0),(F22/B22)^(1/4)-1,"") -> 0.03
A23: Strategic Plan Initiatives (operating, net) | B23: =Inputs!E31 -> 0 | C23: =Inputs!F31 -> 50000 | D23: =Inputs!G31 -> 100000 | E23: =Inputs!H31 -> 150000 | F23: =Inputs!I31 -> 200000
A24: Total Expenses | B24: =SUM(B18:B23) -> 9302740 | C24: =SUM(C18:C23) -> 9651691.8 | D24: =SUM(D18:D23) -> 9981580.5 | E24: =SUM(E18:E23) -> 10191060 | F24: =SUM(F18:F23) -> 10471581 | G24: =IF(AND(B24>0,F24>0),(F24/B24)^(1/4)-1,"") -> 0.030031119
A26: Net Operating Revenue | B26: =B15-B24 -> 1642 | C26: =C15-C24 -> 103231.68 | D26: =D15-D24 -> 51970.772 | E26: =E15-E24 -> 154414.65 | F26: =F15-F24 -> 179360.91
A27: Other Revenue (Development) | B27: =SUMIFS('Forecast Detail'!G$8:G$400,'Forecast Detail'!$B$8:$B$400,"Other Revenue")+SUMIFS('QB Import'!$B$1:$B$600,'QB Import'!$F$1:$F$600,"Other Revenue",'QB Import'!$I$1:$I$600,"UNMAPPED") -> 0 | C27: =SUMIFS('Forecast Detail'!H$8:H$400,'Forecast Detail'!$B$8:$B$400,"Other Revenue")+SUMIFS('QB Import'!$B$1:$B$600,'QB Import'!$F$1:$F$600,"Other Revenue",'QB Import'!$I$1:$I$600,"UNMAPPED") -> 0 | D27: =SUMIFS('Forecast Detail'!I$8:I$400,'Forecast Detail'!$B$8:$B$400,"Other Revenue")+SUMIFS('QB Import'!$B$1:$B$600,'QB Import'!$F$1:$F$600,"Other Revenue",'QB Import'!$I$1:$I$600,"UNMAPPED") -> 0 | E27: =SUMIFS('Forecast Detail'!J$8:J$400,'Forecast Detail'!$B$8:$B$400,"Other Revenue")+SUMIFS('QB Import'!$B$1:$B$600,'QB Import'!$F$1:$F$600,"Other Revenue",'QB Import'!$I$1:$I$600,"UNMAPPED") -> 0 | F27: =SUMIFS('Forecast Detail'!K$8:K$400,'Forecast Detail'!$B$8:$B$400,"Other Revenue")+SUMIFS('QB Import'!$B$1:$B$600,'QB Import'!$F$1:$F$600,"Other Revenue",'QB Import'!$I$1:$I$600,"UNMAPPED") -> 0
A28: Other Expenditures (Development) | B28: =SUMIFS('Forecast Detail'!G$8:G$400,'Forecast Detail'!$B$8:$B$400,"Other Expense")+SUMIFS('QB Import'!$B$1:$B$600,'QB Import'!$F$1:$F$600,"Other Expense",'QB Import'!$I$1:$I$600,"UNMAPPED") -> 0 | C28: =SUMIFS('Forecast Detail'!H$8:H$400,'Forecast Detail'!$B$8:$B$400,"Other Expense")+SUMIFS('QB Import'!$B$1:$B$600,'QB Import'!$F$1:$F$600,"Other Expense",'QB Import'!$I$1:$I$600,"UNMAPPED") -> 0 | D28: =SUMIFS('Forecast Detail'!I$8:I$400,'Forecast Detail'!$B$8:$B$400,"Other Expense")+SUMIFS('QB Import'!$B$1:$B$600,'QB Import'!$F$1:$F$600,"Other Expense",'QB Import'!$I$1:$I$600,"UNMAPPED") -> 0 | E28: =SUMIFS('Forecast Detail'!J$8:J$400,'Forecast Detail'!$B$8:$B$400,"Other Expense")+SUMIFS('QB Import'!$B$1:$B$600,'QB Import'!$F$1:$F$600,"Other Expense",'QB Import'!$I$1:$I$600,"UNMAPPED") -> 0 | F28: =SUMIFS('Forecast Detail'!K$8:K$400,'Forecast Detail'!$B$8:$B$400,"Other Expense")+SUMIFS('QB Import'!$B$1:$B$600,'QB Import'!$F$1:$F$600,"Other Expense",'QB Import'!$I$1:$I$600,"UNMAPPED") -> 0
A29: Net Other Revenue | B29: =B27-B28 -> 0 | C29: =C27-C28 -> 0 | D29: =D27-D28 -> 0 | E29: =E27-E28 -> 0 | F29: =F27-F28 -> 0
A30: NET REVENUE (SURPLUS / DEFICIT) | B30: =B26+B29 -> 1642 | C30: =C26+C29 -> 103231.68 | D30: =D26+D29 -> 51970.772 | E30: =E26+E29 -> 154414.65 | F30: =F26+F29 -> 179360.91
A32: KEY METRICS
A33: Salaries & benefits % of total revenue | B33: =IF(B15=0,0,B18/B15) -> 0.67206065 | C33: =IF(C15=0,0,C18/C15) -> 0.66177094 | D33: =IF(D15=0,0,D18/D15) -> 0.66308189 | E33: =IF(E15=0,0,E18/E15) -> 0.66256945 | F33: =IF(F15=0,0,F18/F15) -> 0.66299129
A34: Net tuition & fees per student | B34: =IF(B6=0,0,B11/B6) -> 15119.213 | C34: =IF(C6=0,0,C11/C6) -> 15737.595 | D34: =IF(D6=0,0,D11/D6) -> 16376.779 | E34: =IF(E6=0,0,E11/E6) -> 17052.264 | F34: =IF(F6=0,0,F11/F6) -> 17697.646
A35: Net revenue margin (% of revenue) | B35: =IF(B15=0,0,B30/B15) -> 0.00017647599 | C35: =IF(C15=0,0,C30/C15) -> 0.010582521 | D35: =IF(D15=0,0,D30/D15) -> 0.0051796986 | E35: =IF(E15=0,0,E30/E15) -> 0.014925816 | F35: =IF(F15=0,0,F30/F15) -> 0.016839911
A36: Capital projects & initiatives (cash) | B36: =-'CF Summary'!B8 -> 0 | C36: =-'CF Summary'!C8 -> 0 | D36: =-'CF Summary'!D8 -> 0 | E36: =-'CF Summary'!E8 -> 0 | F36: =-'CF Summary'!F8 -> 0
A37: Ending cash & reserves | B37: ='CF Summary'!B12 -> 2379207.7 | C37: ='CF Summary'!C12 -> 2586817.6 | D37: ='CF Summary'!D12 -> 2738051 | E37: ='CF Summary'!E12 -> 2989594.7 | F37: ='CF Summary'!F12 -> 3296725.4
A38: Lowest month-end operating cash | B38: ='CF Summary'!B13 -> -31299.821 | C38: ='CF Summary'!C13 -> 131306.32 | D38: ='CF Summary'!D13 -> 238258.55 | E38: ='CF Summary'!E13 -> 427586.45 | F38: ='CF Summary'!F13 -> 653700.89
A39: Days cash on hand | B39: ='CF Summary'!B15 -> 93.350004 | C39: ='CF Summary'!C15 -> 97.826208 | D39: ='CF Summary'!D15 -> 100.12328 | E39: ='CF Summary'!E15 -> 107.07444 | F39: ='CF Summary'!F15 -> 114.91147
A41: Source: FY27 = QuickBooks budget import; FY28-FY31 = forecast per Inputs and Forecast Detail. Cash on a cash basis.
A43: IMPORT CHECKS (not printed)
A44: Revenue: import detail vs summary FY27 | B44: =SUMIFS('QB Import'!$B$1:$B$600,'QB Import'!$E$1:$E$600,"Revenue",'QB Import'!$G$1:$G$600,1)+SUMIFS('QB Import'!$B$1:$B$600,'QB Import'!$E$1:$E$600,"COGS",'QB Import'!$G$1:$G$600,1)-SUM(B11:B14) -> 0
A45: Expenses: import detail vs summary FY27 | B45: =SUMIFS('QB Import'!$B$1:$B$600,'QB Import'!$E$1:$E$600,"Expense",'QB Import'!$G$1:$G$600,1)-SUM(B18:B22) -> 0
A46: Overall status | B46: =IF(AND(ABS(B44)<1,ABS(B45)<1,ABS(B47)<1,ABS(B48)<1,B49=0,B50=0),"OK - ties to QuickBooks","CHECK - "&B49&" unmapped account(s); see rows 44-50") -> OK - ties to QuickBooks
A47: Other net: import detail vs summary FY27 | B47: =SUMIFS('QB Import'!$B$1:$B$600,'QB Import'!$E$1:$E$600,"Other Revenue",'QB Import'!$G$1:$G$600,1)-SUMIFS('QB Import'!$B$1:$B$600,'QB Import'!$E$1:$E$600,"Other Expense",'QB Import'!$G$1:$G$600,1)-B29 -> 0
...

Sheet Inputs
A1: INPUTS & ASSUMPTIONS
A2: Blue-on-yellow cells are inputs. Everything else is calculated. FY27 amounts come from the QuickBooks import.
A4: Fiscal year | C4: ="FY"&TEXT(C5,"yy") -> FY27 | D4: ="FY"&TEXT(D5,"yy") -> FY28 | E4: ="FY"&TEXT(E5,"yy") -> FY29 | F4: ="FY"&TEXT(F5,"yy") -> FY30 | G4: ="FY"&TEXT(G5,"yy") -> FY31
A5: Fiscal year ending | C5: 46568 | D5: =EOMONTH(C5,12) -> 46934 | E5: =EOMONTH(D5,12) -> 47299 | F5: =EOMONTH(E5,12) -> 47664 | G5: =EOMONTH(F5,12) -> 48029
A6: Fiscal year starting | C6: =EOMONTH(C5,-12)+1 -> 46204 | D6: =EOMONTH(D5,-12)+1 -> 46569 | E6: =EOMONTH(E5,-12)+1 -> 46935 | F6: =EOMONTH(F5,-12)+1 -> 47300 | G6: =EOMONTH(G5,-12)+1 -> 47665
A8: Growth assumptions
A9: Tuition rate increase % | C9: 0.04 | D9: 0.05 | E9: 0.045 | F9: 0.045 | G9: 0.04 | H9: FY27 shown for reference; rates already set in the budget
A10: Salary increase % | C10: 0.025 | D10: 0.03 | E10: 0.03 | F10: 0.03 | G10: 0.03 | H10: Applies to lines using the 'Salary' method
A11: Benefits cost increase % (medical, dental) | C11: 0.03 | D11: 0.03 | E11: 0.03 | F11: 0.03 | G11: 0.03 | H11: Lines using the 'Benefits' method
A12: General inflation % | C12: 0.03 | D12: 0.03 | E12: 0.03 | F12: 0.03 | G12: 0.03 | H12: Lines using 'Inflation' and 'Per Student'
A13: Yield on interest-earning balances % | D13: 0.014 | E13: 0.014 | F13: 0.014 | G13: 0.014 | H13: Applied to prior year-end balances; 'Reserve Yield' method
A14: Final mortgage payment date | C14: 47422 | H14: Lines using the 'Debt' method stop after this month
A15: Months of debt service paid in fiscal year | C15: =MAX(0,MIN(12,(YEAR($C$14)-YEAR(C6))*12+MONTH($C$14)-MONTH(C6)+1)) -> 12 | D15: =MAX(0,MIN(12,(YEAR($C$14)-YEAR(D6))*12+MONTH($C$14)-MONTH(D6)+1)) -> 12 | E15: =MAX(0,MIN(12,(YEAR($C$14)-YEAR(E6))*12+MONTH($C$14)-MONTH(E6)+1)) -> 12 | F15: =MAX(0,MIN(12,(YEAR($C$14)-YEAR(F6))*12+MONTH($C$14)-MONTH(F6)+1)) -> 4 | G15: =MAX(0,MIN(12,(YEAR($C$14)-YEAR(G6))*12+MONTH($C$14)-MONTH(G6)+1)) -> 0
A16: Interest-earning balance at prior year-end | D16: =$D$60+SUM($C$48:C48) -> 2071787.9 | E16: =$D$60+SUM($C$48:D48) -> 2071787.9 | F16: =$D$60+SUM($C$48:E48) -> 2071787.9 | G16: =$D$60+SUM($C$48:F48) -> 2071787.9 | H16: Opening earning balances + reserve funding to date
A18: Strategic plan initiatives (Operating = flows through the P&L; Capital = cash only, no P&L)
A19: Initiative | B19: Type | C19: On? (Y/N) | D19: Spend month (0=even, 1=Jul) | E19: ="Cost "&C$4 -> Cost FY27 | F19: ="Cost "&D$4 -> Cost FY28 | G19: ="Cost "&E$4 -> Cost FY29 | H19: ="Cost "&F$4 -> Cost FY30 | I19: ="Cost "&G$4 -> Cost FY31 | J19: ="Offset "&C$4 -> Offset FY27 | K19: ="Offset "&D$4 -> Offset FY28 | L19: ="Offset "&E$4 -> Offset FY29 | M19: ="Offset "&F$4 -> Offset FY30 | N19: ="Offset "&G$4 -> Offset FY31
A20: Additional Lower School teacher (per prior model: +$50k/yr) | B20: Operating | C20: Y | D20: 0 | E20: 0 | F20: 50000 | G20: 100000 | H20: 150000 | I20: 200000 | J20: 0 | K20: 0 | L20: 0 | M20: 0 | N20: 0
A21: Lower School reconfiguration (enter cost) | B21: Capital | C21: Y | D21: 0 | E21: 0 | F21: 0 | G21: 0 | H21: 0 | I21: 0 | J21: 0 | K21: 0 | L21: 0 | M21: 0 | N21: 0
A31: Operating initiatives - net cost to P&L | E31: =SUMPRODUCT(($B$20:$B$29="Operating")*($C$20:$C$29="Y")*(E$20:E$29-J$20:J$29)) -> 0 | F31: =SUMPRODUCT(($B$20:$B$29="Operating")*($C$20:$C$29="Y")*(F$20:F$29-K$20:K$29)) -> 50000 | G31: =SUMPRODUCT(($B$20:$B$29="Operating")*($C$20:$C$29="Y")*(G$20:G$29-L$20:L$29)) -> 100000 | H31: =SUMPRODUCT(($B$20:$B$29="Operating")*($C$20:$C$29="Y")*(H$20:H$29-M$20:M$29)) -> 150000 | I31: =SUMPRODUCT(($B$20:$B$29="Operating")*($C$20:$C$29="Y")*(I$20:I$29-N$20:N$29)) -> 200000
A32: Capital initiatives - net cash cost | E32: =SUMPRODUCT(($B$20:$B$29="Capital")*($C$20:$C$29="Y")*(E$20:E$29-J$20:J$29)) -> 0 | F32: =SUMPRODUCT(($B$20:$B$29="Capital")*($C$20:$C$29="Y")*(F$20:F$29-K$20:K$29)) -> 0 | G32: =SUMPRODUCT(($B$20:$B$29="Capital")*($C$20:$C$29="Y")*(G$20:G$29-L$20:L$29)) -> 0 | H32: =SUMPRODUCT(($B$20:$B$29="Capital")*($C$20:$C$29="Y")*(H$20:H$29-M$20:M$29)) -> 0 | I32: =SUMPRODUCT(($B$20:$B$29="Capital")*($C$20:$C$29="Y")*(I$20:I$29-N$20:N$29)) -> 0
A34: Capital projects & equipment (cash only; outside the operating P&L)
A35: Project | B35: Spend month (0=even, 1=Jul) | C35: =C$4 -> FY27 | D35: =D$4 -> FY28 | E35: =E$4 -> FY29 | F35: =F$4 -> FY30 | G35: =G$4 -> FY31
A36: Example: roof replacement | B36: 0
B37: 0
B38: 0
B39: 0
B40: 0
B41: 0
A42: Total capital projects | C42: =SUM(C36:C41) -> 0 | D42: =SUM(D36:D41) -> 0 | E42: =SUM(E36:E41) -> 0 | F42: =SUM(F36:F41) -> 0 | G42: =SUM(G36:G41) -> 0
A44: Reserve funding (transfer from operating cash to reserves; cash-neutral overall)
A45: Transfer | B45: Month (0=even, 1=Jul) | C45: =C$4 -> FY27 | D45: =D$4 -> FY28 | E45: =E$4 -> FY29 | F45: =F$4 -> FY30 | G45: =G$4 -> FY31
A46: Operating reserve funding | B46: 12 | C46: 0 | D46: 0 | E46: 0 | F46: 0 | G46: 0
A47: Repair & replacement (R&R) reserve funding | B47: 12 | C47: 0 | D47: 0 | E47: 0 | F47: 0 | G47: 0
A48: Total reserve funding | C48: =SUM(C46:C47) -> 0 | D48: =SUM(D46:D47) -> 0 | E48: =SUM(E46:E47) -> 0 | F48: =SUM(F46:F47) -> 0 | G48: =SUM(G46:G47) -> 0
A50: Opening cash & reserve balances
A51: Balances as of (start of FY27 = 6/30/2026 recommended) | B51: 46203
A52: Account | B52: Available for operations? (Y/N) | C52: Earns interest? (Y/N) | D52: Balance
A53: Operating Account | B53: Y | C53: N | D53: 134596.05 | E53: Balances seeded from the 1/31/26 figures in the old model - UPDATE.
A54: Contingency | B54: N | C54: Y | D54: 441027.78
A55: S4K | B55: N | C55: Y | D55: 167658.2
...

Sheet Enrollment
A1: ENROLLMENT & TUITION RATES
A2: FY27 enrollment and rates are inputs. Later years roll each grade forward: prior grade x retention + new students.
A3: Enrollment by grade
A4: Grade | B4: =Inputs!C$4 -> FY27 | C4: =Inputs!D$4 -> FY28 | D4: =Inputs!E$4 -> FY29 | E4: =Inputs!F$4 -> FY30 | F4: =Inputs!G$4 -> FY31
A5: K-3 (5 day) | B5: 21 | C5: =C49 -> 20 | D5: =D49 -> 20 | E5: =E49 -> 20 | F5: =F49 -> 20
A6: K-3 (3 day) | B6: 4 | C6: =C50 -> 4 | D6: =D50 -> 4 | E6: =E50 -> 4 | F6: =F50 -> 4
A7: K-4 | B7: 44 | C7: =ROUND((B5+B6)*$B51+C51,0) -> 37 | D7: =ROUND((C5+C6)*$B51+D51,0) -> 36 | E7: =ROUND((D5+D6)*$B51+E51,0) -> 36 | F7: =ROUND((E5+E6)*$B51+F51,0) -> 36
A8: K5 | B8: 53 | C8: =ROUND(B7*$B52+C52,0) -> 45 | D8: =ROUND(C7*$B52+D52,0) -> 39 | E8: =ROUND(D7*$B52+E52,0) -> 38 | F8: =ROUND(E7*$B52+F52,0) -> 38
A9: 1st | B9: 45 | C9: =ROUND(B8*$B53+C53,0) -> 53 | D9: =ROUND(C8*$B53+D53,0) -> 45 | E9: =ROUND(D8*$B53+E53,0) -> 39 | F9: =ROUND(E8*$B53+F53,0) -> 38
A10: 2nd | B10: 37 | C10: =ROUND(B9*$B54+C54,0) -> 44 | D10: =ROUND(C9*$B54+D54,0) -> 52 | E10: =ROUND(D9*$B54+E54,0) -> 44 | F10: =ROUND(E9*$B54+F54,0) -> 38
A11: 3rd | B11: 33 | C11: =ROUND(B10*$B55+C55,0) -> 37 | D11: =ROUND(C10*$B55+D55,0) -> 43 | E11: =ROUND(D10*$B55+E55,0) -> 51 | F11: =ROUND(E10*$B55+F55,0) -> 43
A12: 4th | B12: 36 | C12: =ROUND(B11*$B56+C56,0) -> 33 | D12: =ROUND(C11*$B56+D56,0) -> 37 | E12: =ROUND(D11*$B56+E56,0) -> 42 | F12: =ROUND(E11*$B56+F56,0) -> 50
A13: 5th | B13: 36 | C13: =ROUND(B12*$B57+C57,0) -> 36 | D13: =ROUND(C12*$B57+D57,0) -> 33 | E13: =ROUND(D12*$B57+E57,0) -> 37 | F13: =ROUND(E12*$B57+F57,0) -> 41
A14: 6th | B14: 40 | C14: =ROUND(B13*$B58+C58,0) -> 39 | D14: =ROUND(C13*$B58+D58,0) -> 39 | E14: =ROUND(D13*$B58+E58,0) -> 36 | F14: =ROUND(E13*$B58+F58,0) -> 40
A15: 7th | B15: 34 | C15: =ROUND(B14*$B59+C59,0) -> 40 | D15: =ROUND(C14*$B59+D59,0) -> 39 | E15: =ROUND(D14*$B59+E59,0) -> 39 | F15: =ROUND(E14*$B59+F59,0) -> 37
A16: 8th | B16: 37 | C16: =ROUND(B15*$B60+C60,0) -> 35 | D16: =ROUND(C15*$B60+D60,0) -> 40 | E16: =ROUND(D15*$B60+E60,0) -> 39 | F16: =ROUND(E15*$B60+F60,0) -> 39
A17: 9th | B17: 45 | C17: =ROUND(B16*$B61+C61,0) -> 40 | D17: =ROUND(C16*$B61+D61,0) -> 38 | E17: =ROUND(D16*$B61+E61,0) -> 42 | F17: =ROUND(E16*$B61+F61,0) -> 41
A18: 10th | B18: 44 | C18: =ROUND(B17*$B62+C62,0) -> 44 | D18: =ROUND(C17*$B62+D62,0) -> 39 | E18: =ROUND(D17*$B62+E62,0) -> 37 | F18: =ROUND(E17*$B62+F62,0) -> 41
A19: 11th | B19: 43 | C19: =ROUND(B18*$B63+C63,0) -> 43 | D19: =ROUND(C18*$B63+D63,0) -> 43 | E19: =ROUND(D18*$B63+E63,0) -> 38 | F19: =ROUND(E18*$B63+F63,0) -> 37
A20: 12th | B20: 30 | C20: =ROUND(B19*$B64+C64,0) -> 41 | D20: =ROUND(C19*$B64+D64,0) -> 41 | E20: =ROUND(D19*$B64+E64,0) -> 41 | F20: =ROUND(E19*$B64+F64,0) -> 36
A21: Total enrollment | B21: =SUM(B5:B20) -> 582 | C21: =SUM(C5:C20) -> 591 | D21: =SUM(D5:D20) -> 588 | E21: =SUM(E5:E20) -> 583 | F21: =SUM(F5:F20) -> 579
A22: Change vs prior year | C22: =C21-B21 -> 9 | D22: =D21-C21 -> -3 | E22: =E21-D21 -> -5 | F22: =F21-E21 -> -4
A23: Tuition potential (enrollment x rate) | B23: =SUMPRODUCT(B5:B20,B29:B44) -> 9315096.2 | C23: =SUMPRODUCT(C5:C20,C29:C44) -> 10018178 | D23: =SUMPRODUCT(D5:D20,D29:D44) -> 10433240 | E23: =SUMPRODUCT(E5:E20,E29:E44) -> 10806025 | F23: =SUMPRODUCT(F5:F20,F29:F44) -> 11170544
A24: Tuition index (FY27 = 1.000) | B24: =B23/$B$23 -> 1 | C24: =C23/$B$23 -> 1.0754776 | D24: =D23/$B$23 -> 1.1200357 | E24: =E23/$B$23 -> 1.1600551 | F24: =F23/$B$23 -> 1.1991872
A25: Average rate per student | B25: =B23/B21 -> 16005.32 | C25: =C23/C21 -> 16951.231 | D25: =D23/D21 -> 17743.606 | E25: =E23/E21 -> 18535.206 | F25: =F23/F21 -> 19292.822
A27: Tuition rate by grade (before discounts)
A28: Grade | B28: =Inputs!C$4 -> FY27 | C28: =Inputs!D$4 -> FY28 | D28: =Inputs!E$4 -> FY29 | E28: =Inputs!F$4 -> FY30 | F28: =Inputs!G$4 -> FY31
A29: K-3 (5 day) | B29: 8958.56 | C29: =B29*(1+Inputs!D$9) -> 9406.488 | D29: =C29*(1+Inputs!E$9) -> 9829.78 | E29: =D29*(1+Inputs!F$9) -> 10272.12 | F29: =E29*(1+Inputs!G$9) -> 10683.005
A30: K-3 (3 day) (rate not in old model - enter) | B30: 5400 | C30: =B30*(1+Inputs!D$9) -> 5670 | D30: =C30*(1+Inputs!E$9) -> 5925.15 | E30: =D30*(1+Inputs!F$9) -> 6191.7818 | F30: =E30*(1+Inputs!G$9) -> 6439.453
A31: K-4 | B31: 10510.24 | C31: =B31*(1+Inputs!D$9) -> 11035.752 | D31: =C31*(1+Inputs!E$9) -> 11532.361 | E31: =D31*(1+Inputs!F$9) -> 12051.317 | F31: =E31*(1+Inputs!G$9) -> 12533.37
A32: K5 | B32: 13198.64 | C32: =B32*(1+Inputs!D$9) -> 13858.572 | D32: =C32*(1+Inputs!E$9) -> 14482.208 | E32: =D32*(1+Inputs!F$9) -> 15133.907 | F32: =E32*(1+Inputs!G$9) -> 15739.263
A33: 1st | B33: 15895.36 | C33: =B33*(1+Inputs!D$9) -> 16690.128 | D33: =C33*(1+Inputs!E$9) -> 17441.184 | E33: =D33*(1+Inputs!F$9) -> 18226.037 | F33: =E33*(1+Inputs!G$9) -> 18955.079
A34: 2nd | B34: 15895.36 | C34: =B34*(1+Inputs!D$9) -> 16690.128 | D34: =C34*(1+Inputs!E$9) -> 17441.184 | E34: =D34*(1+Inputs!F$9) -> 18226.037 | F34: =E34*(1+Inputs!G$9) -> 18955.079
A35: 3rd | B35: 15895.36 | C35: =B35*(1+Inputs!D$9) -> 16690.128 | D35: =C35*(1+Inputs!E$9) -> 17441.184 | E35: =D35*(1+Inputs!F$9) -> 18226.037 | F35: =E35*(1+Inputs!G$9) -> 18955.079
A36: 4th | B36: 16672.24 | C36: =B36*(1+Inputs!D$9) -> 17505.852 | D36: =C36*(1+Inputs!E$9) -> 18293.615 | E36: =D36*(1+Inputs!F$9) -> 19116.828 | F36: =E36*(1+Inputs!G$9) -> 19881.501
A37: 5th | B37: 16672.24 | C37: =B37*(1+Inputs!D$9) -> 17505.852 | D37: =C37*(1+Inputs!E$9) -> 18293.615 | E37: =D37*(1+Inputs!F$9) -> 19116.828 | F37: =E37*(1+Inputs!G$9) -> 19881.501
A38: 6th | B38: 17899.44 | C38: =B38*(1+Inputs!D$9) -> 18794.412 | D38: =C38*(1+Inputs!E$9) -> 19640.161 | E38: =D38*(1+Inputs!F$9) -> 20523.968 | F38: =E38*(1+Inputs!G$9) -> 21344.926
A39: 7th | B39: 17899.44 | C39: =B39*(1+Inputs!D$9) -> 18794.412 | D39: =C39*(1+Inputs!E$9) -> 19640.161 | E39: =D39*(1+Inputs!F$9) -> 20523.968 | F39: =E39*(1+Inputs!G$9) -> 21344.926
A40: 8th | B40: 17899.44 | C40: =B40*(1+Inputs!D$9) -> 18794.412 | D40: =C40*(1+Inputs!E$9) -> 19640.161 | E40: =D40*(1+Inputs!F$9) -> 20523.968 | F40: =E40*(1+Inputs!G$9) -> 21344.926
... A44: 12th | B44: 18075.2 | C44: =B44*(1+Inputs!D$9) -> 18978.96 | D44: =C44*(1+Inputs!E$9) -> 19833.013 | E44: =D44*(1+Inputs!F$9) -> 20725.499 | F44: =E44*(1+Inputs!G$9) -> 21554.519
...

Sheet Forecast Detail
A1: FORECAST DETAIL - by QuickBooks account
A2: FY27 = QuickBooks budget import. Choose a forecast method per line (column E). Use 'Manual' + columns L:O to type amounts directly.
D4: Total enrollment | G4: =Enrollment!B21 -> 582 | H4: =Enrollment!C21 -> 591 | I4: =Enrollment!D21 -> 588 | J4: =Enrollment!E21 -> 583 | K4: =Enrollment!F21 -> 579
D5: Tuition index | G5: =Enrollment!B24 -> 1 | H5: =Enrollment!C24 -> 1.0754776 | I5: =Enrollment!D24 -> 1.1200357 | J5: =Enrollment!E24 -> 1.1600551 | K5: =Enrollment!F24 -> 1.1991872
D6: Salary-method lines total | G6: =SUMIF($E$8:$E$400,"Salary",G$8:G$400) -> 5098000 | H6: =G6*(1+Inputs!D$10) -> 5250940 | I6: =H6*(1+Inputs!E$10) -> 5408468.2 | J6: =I6*(1+Inputs!F$10) -> 5570722.2 | K6: =J6*(1+Inputs!G$10) -> 5737843.9
A7: Type | B7: Major Category | C7: Key | D7: Description | E7: Method | F7: Cash Timing | G7: =Inputs!C$4 -> FY27 | H7: =Inputs!D$4 -> FY28 | I7: =Inputs!E$4 -> FY29 | J7: =Inputs!F$4 -> FY30 | K7: =Inputs!G$4 -> FY31 | L7: ="Manual "&Inputs!D$4 -> Manual FY28 | M7: ="Manual "&Inputs!E$4 -> Manual FY29 | N7: ="Manual "&Inputs!F$4 -> Manual FY30 | O7: ="Manual "&Inputs!G$4 -> Manual FY31
A8: Revenue | B8: 1 Tuition and Fees | C8: 400186 | D8: 400186 Tuition Income | E8: Tuition Index | F8: Tuition Plan | G8: =SUMIFS('QB Import'!$B$1:$B$600,'QB Import'!$H$1:$H$600,$C8,'QB Import'!$G$1:$G$600,1) -> 7858980 | H8: =IF($E8="Manual",L8,IF($E8="Flat",G8,IF($E8="Inflation",G8*(1+Inputs!D$12),IF($E8="Salary",G8*(1+Inputs!D$10),IF($E8="Benefits",G8*(1+Inputs!D$11),IF($E8="Per Student",G8*H$4/G$4*(1+Inputs!D$12),IF($E8="Enrollment",G8*H$4/G$4,IF($E8="Tuition Index",G8*H$5/G$5,IF($E8="% of Salaries",IF($G$6=0,0,$G8/$G$6*H$6),IF($E8="Debt",$G8*Inputs!D$15/12,IF($E8="Reserve Yield",Inputs!D$13*Inputs!D$16,IF($E8="Trend",IF(ISNUMBER(Trend!$Q47),Trend!$Q47,G8),G8)))))))))))) -> 8452157.2 | I8: =IF($E8="Manual",M8,IF($E8="Flat",H8,IF($E8="Inflation",H8*(1+Inputs!E$12),IF($E8="Salary",H8*(1+Inputs!E$10),IF($E8="Benefits",H8*(1+Inputs!E$11),IF($E8="Per Student",H8*I$4/H$4*(1+Inputs!E$12),IF($E8="Enrollment",H8*I$4/H$4,IF($E8="Tuition Index",H8*I$5/H$5,IF($E8="% of Salaries",IF($G$6=0,0,$G8/$G$6*I$6),IF($E8="Debt",$G8*Inputs!E$15/12,IF($E8="Reserve Yield",Inputs!E$13*Inputs!E$16,IF($E8="Trend",H8*(1+Inputs!E$12),H8)))))))))))) -> 8802338.1 | J8: =IF($E8="Manual",N8,IF($E8="Flat",I8,IF($E8="Inflation",I8*(1+Inputs!F$12),IF($E8="Salary",I8*(1+Inputs!F$10),IF($E8="Benefits",I8*(1+Inputs!F$11),IF($E8="Per Student",I8*J$4/I$4*(1+Inputs!F$12),IF($E8="Enrollment",I8*J$4/I$4,IF($E8="Tuition Index",I8*J$5/I$5,IF($E8="% of Salaries",IF($G$6=0,0,$G8/$G$6*J$6),IF($E8="Debt",$G8*Inputs!F$15/12,IF($E8="Reserve Yield",Inputs!F$13*Inputs!F$16,IF($E8="Trend",I8*(1+Inputs!F$12),I8)))))))))))) -> 9116849.9 | K8: =IF($E8="Manual",O8,IF($E8="Flat",J8,IF($E8="Inflation",J8*(1+Inputs!G$12),IF($E8="Salary",J8*(1+Inputs!G$10),IF($E8="Benefits",J8*(1+Inputs!G$11),IF($E8="Per Student",J8*K$4/J$4*(1+Inputs!G$12),IF($E8="Enrollment",J8*K$4/J$4,IF($E8="Tuition Index",J8*K$5/J$5,IF($E8="% of Salaries",IF($G$6=0,0,$G8/$G$6*K$6),IF($E8="Debt",$G8*Inputs!G$15/12,IF($E8="Reserve Yield",Inputs!G$13*Inputs!G$16,IF($E8="Trend",J8*(1+Inputs!G$12),J8)))))))))))) -> 9424388.2
A9: Revenue | B9: 1 Tuition and Fees | C9: 400187 | D9: 400187 Scholarship for Kids Tuition | E9: Manual | F9: Tuition Plan | G9: =SUMIFS('QB Import'!$B$1:$B$600,'QB Import'!$H$1:$H$600,$C9,'QB Import'!$G$1:$G$600,1) -> 410000 | H9: =IF($E9="Manual",L9,IF($E9="Flat",G9,IF($E9="Inflation",G9*(1+Inputs!D$12),IF($E9="Salary",G9*(1+Inputs!D$10),IF($E9="Benefits",G9*(1+Inputs!D$11),IF($E9="Per Student",G9*H$4/G$4*(1+Inputs!D$12),IF($E9="Enrollment",G9*H$4/G$4,IF($E9="Tuition Index",G9*H$5/G$5,IF($E9="% of Salaries",IF($G$6=0,0,$G9/$G$6*H$6),IF($E9="Debt",$G9*Inputs!D$15/12,IF($E9="Reserve Yield",Inputs!D$13*Inputs!D$16,IF($E9="Trend",IF(ISNUMBER(Trend!$Q48),Trend!$Q48,G9),G9)))))))))))) -> 380000 | I9: =IF($E9="Manual",M9,IF($E9="Flat",H9,IF($E9="Inflation",H9*(1+Inputs!E$12),IF($E9="Salary",H9*(1+Inputs!E$10),IF($E9="Benefits",H9*(1+Inputs!E$11),IF($E9="Per Student",H9*I$4/H$4*(1+Inputs!E$12),IF($E9="Enrollment",H9*I$4/H$4,IF($E9="Tuition Index",H9*I$5/H$5,IF($E9="% of Salaries",IF($G$6=0,0,$G9/$G$6*I$6),IF($E9="Debt",$G9*Inputs!E$15/12,IF($E9="Reserve Yield",Inputs!E$13*Inputs!E$16,IF($E9="Trend",H9*(1+Inputs!E$12),H9)))))))))))) -> 360000 | J9: =IF($E9="Manual",N9,IF($E9="Flat",I9,IF($E9="Inflation",I9*(1+Inputs!F$12),IF($E9="Salary",I9*(1+Inputs!F$10),IF($E9="Benefits",I9*(1+Inputs!F$11),IF($E9="Per Student",I9*J$4/I$4*(1+Inputs!F$12),IF($E9="Enrollment",I9*J$4/I$4,IF($E9="Tuition Index",I9*J$5/I$5,IF($E9="% of Salaries",IF($G$6=0,0,$G9/$G$6*J$6),IF($E9="Debt",$G9*Inputs!F$15/12,IF($E9="Reserve Yield",Inputs!F$13*Inputs!F$16,IF($E9="Trend",I9*(1+Inputs!F$12),I9)))))))))))) -> 360000 | K9: =IF($E9="Manual",O9,IF($E9="Flat",J9,IF($E9="Inflation",J9*(1+Inputs!G$12),IF($E9="Salary",J9*(1+Inputs!G$10),IF($E9="Benefits",J9*(1+Inputs!G$11),IF($E9="Per Student",J9*K$4/J$4*(1+Inputs!G$12),IF($E9="Enrollment",J9*K$4/J$4,IF($E9="Tuition Index",J9*K$5/J$5,IF($E9="% of Salaries",IF($G$6=0,0,$G9/$G$6*K$6),IF($E9="Debt",$G9*Inputs!G$15/12,IF($E9="Reserve Yield",Inputs!G$13*Inputs!G$16,IF($E9="Trend",J9*(1+Inputs!G$12),J9)))))))))))) -> 360000 | L9: 380000 | M9: 360000 | N9: 360000 | O9: 360000
A10: Revenue | B10: 1 Tuition and Fees | C10: 400188 | D10: 400188 Choose Act Tuition | E10: Flat | F10: Tuition Plan | G10: =SUMIFS('QB Import'!$B$1:$B$600,'QB Import'!$H$1:$H$600,$C10,'QB Import'!$G$1:$G$600,1) -> 616000 | H10: =IF($E10="Manual",L10,IF($E10="Flat",G10,IF($E10="Inflation",G10*(1+Inputs!D$12),IF($E10="Salary",G10*(1+Inputs!D$10),IF($E10="Benefits",G10*(1+Inputs!D$11),IF($E10="Per Student",G10*H$4/G$4*(1+Inputs!D$12),IF($E10="Enrollment",G10*H$4/G$4,IF($E10="Tuition Index",G10*H$5/G$5,IF($E10="% of Salaries",IF($G$6=0,0,$G10/$G$6*H$6),IF($E10="Debt",$G10*Inputs!D$15/12,IF($E10="Reserve Yield",Inputs!D$13*Inputs!D$16,IF($E10="Trend",IF(ISNUMBER(Trend!$Q49),Trend!$Q49,G10),G10)))))))))))) -> 616000 | I10: =IF($E10="Manual",M10,IF($E10="Flat",H10,IF($E10="Inflation",H10*(1+Inputs!E$12),IF($E10="Salary",H10*(1+Inputs!E$10),IF($E10="Benefits",H10*(1+Inputs!E$11),IF($E10="Per Student",H10*I$4/H$4*(1+Inputs!E$12),IF($E10="Enrollment",H10*I$4/H$4,IF($E10="Tuition Index",H10*I$5/H$5,IF($E10="% of Salaries",IF($G$6=0,0,$G10/$G$6*I$6),IF($E10="Debt",$G10*Inputs!E$15/12,IF($E10="Reserve Yield",Inputs!E$13*Inputs!E$16,IF($E10="Trend",H10*(1+Inputs!E$12),H10)))))))))))) -> 616000 | J10: =IF($E10="Manual",N10,IF($E10="Flat",I10,IF($E10="Inflation",I10*(1+Inputs!F$12),IF($E10="Salary",I10*(1+Inputs!F$10),IF($E10="Benefits",I10*(1+Inputs!F$11),IF($E10="Per Student",I10*J$4/I$4*(1+Inputs!F$12),IF($E10="Enrollment",I10*J$4/I$4,IF($E10="Tuition Index",I10*J$5/I$5,IF($E10="% of Salaries",IF($G$6=0,0,$G10/$G$6*J$6),IF($E10="Debt",$G10*Inputs!F$15/12,IF($E10="Reserve Yield",Inputs!F$13*Inputs!F$16,IF($E10="Trend",I10*(1+Inputs!F$12),I10)))))))))))) -> 616000 | K10: =IF($E10="Manual",O10,IF($E10="Flat",J10,IF($E10="Inflation",J10*(1+Inputs!G$12),IF($E10="Salary",J10*(1+Inputs!G$10),IF($E10="Benefits",J10*(1+Inputs!G$11),IF($E10="Per Student",J10*K$4/J$4*(1+Inputs!G$12),IF($E10="Enrollment",J10*K$4/J$4,IF($E10="Tuition Index",J10*K$5/J$5,IF($E10="% of Salaries",IF($G$6=0,0,$G10/$G$6*K$6),IF($E10="Debt",$G10*Inputs!G$15/12,IF($E10="Reserve Yield",Inputs!G$13*Inputs!G$16,IF($E10="Trend",J10*(1+Inputs!G$12),J10)))))))))))) -> 616000
A11: Revenue | B11: 1 Tuition and Fees | C11: 400189 | D11: 400189 AOSF Tuition | E11: Flat | F11: Tuition Plan | G11: =SUMIFS('QB Import'!$B$1:$B$600,'QB Import'!$H$1:$H$600,$C11,'QB Import'!$G$1:$G$600,1) -> 0 | H11: =IF($E11="Manual",L11,IF($E11="Flat",G11,IF($E11="Inflation",G11*(1+Inputs!D$12),IF($E11="Salary",G11*(1+Inputs!D$10),IF($E11="Benefits",G11*(1+Inputs!D$11),IF($E11="Per Student",G11*H$4/G$4*(1+Inputs!D$12),IF($E11="Enrollment",G11*H$4/G$4,IF($E11="Tuition Index",G11*H$5/G$5,IF($E11="% of Salaries",IF($G$6=0,0,$G11/$G$6*H$6),IF($E11="Debt",$G11*Inputs!D$15/12,IF($E11="Reserve Yield",Inputs!D$13*Inputs!D$16,IF($E11="Trend",IF(ISNUMBER(Trend!$Q50),Trend!$Q50,G11),G11)))))))))))) -> 0 | I11: =IF($E11="Manual",M11,IF($E11="Flat",H11,IF($E11="Inflation",H11*(1+Inputs!E$12),IF($E11="Salary",H11*(1+Inputs!E$10),IF($E11="Benefits",H11*(1+Inputs!E$11),IF($E11="Per Student",H11*I$4/H$4*(1+Inputs!E$12),IF($E11="Enrollment",H11*I$4/H$4,IF($E11="Tuition Index",H11*I$5/H$5,IF($E11="% of Salaries",IF($G$6=0,0,$G11/$G$6*I$6),IF($E11="Debt",$G11*Inputs!E$15/12,IF($E11="Reserve Yield",Inputs!E$13*Inputs!E$16,IF($E11="Trend",H11*(1+Inputs!E$12),H11)))))))))))) -> 0 | J11: =IF($E11="Manual",N11,IF($E11="Flat",I11,IF($E11="Inflation",I11*(1+Inputs!F$12),IF($E11="Salary",I11*(1+Inputs!F$10),IF($E11="Benefits",I11*(1+Inputs!F$11),IF($E11="Per Student",I11*J$4/I$4*(1+Inputs!F$12),IF($E11="Enrollment",I11*J$4/I$4,IF($E11="Tuition Index",I11*J$5/I$5,IF($E11="% of Salaries",IF($G$6=0,0,$G11/$G$6*J$6),IF($E11="Debt",$G11*Inputs!F$15/12,IF($E11="Reserve Yield",Inputs!F$13*Inputs!F$16,IF($E11="Trend",I11*(1+Inputs!F$12),I11)))))))))))) -> 0 | K11: =IF($E11="Manual",O11,IF($E11="Flat",J11,IF($E11="Inflation",J11*(1+Inputs!G$12),IF($E11="Salary",J11*(1+Inputs!G$10),IF($E11="Benefits",J11*(1+Inputs!G$11),IF($E11="Per Student",J11*K$4/J$4*(1+Inputs!G$12),IF($E11="Enrollment",J11*K$4/J$4,IF($E11="Tuition Index",J11*K$5/J$5,IF($E11="% of Salaries",IF($G$6=0,0,$G11/$G$6*K$6),IF($E11="Debt",$G11*Inputs!G$15/12,IF($E11="Reserve Yield",Inputs!G$13*Inputs!G$16,IF($E11="Trend",J11*(1+Inputs!G$12),J11)))))))))))) -> 0
A12: Revenue | B12: 1 Tuition and Fees | C12: 400180 | D12: 400180 Building Fees | E12: Manual | F12: Jul Lump | G12: =SUMIFS('QB Import'!$B$1:$B$600,'QB Import'!$H$1:$H$600,$C12,'QB Import'!$G$1:$G$600,1) -> 35000 | H12: =IF($E12="Manual",L12,IF($E12="Flat",G12,IF($E12="Inflation",G12*(1+Inputs!D$12),IF($E12="Salary",G12*(1+Inputs!D$10),IF($E12="Benefits",G12*(1+Inputs!D$11),IF($E12="Per Student",G12*H$4/G$4*(1+Inputs!D$12),IF($E12="Enrollment",G12*H$4/G$4,IF($E12="Tuition Index",G12*H$5/G$5,IF($E12="% of Salaries",IF($G$6=0,0,$G12/$G$6*H$6),IF($E12="Debt",$G12*Inputs!D$15/12,IF($E12="Reserve Yield",Inputs!D$13*Inputs!D$16,IF($E12="Trend",IF(ISNUMBER(Trend!$Q51),Trend!$Q51,G12),G12)))))))))))) -> 0 | I12: =IF($E12="Manual",M12,IF($E12="Flat",H12,IF($E12="Inflation",H12*(1+Inputs!E$12),IF($E12="Salary",H12*(1+Inputs!E$10),IF($E12="Benefits",H12*(1+Inputs!E$11),IF($E12="Per Student",H12*I$4/H$4*(1+Inputs!E$12),IF($E12="Enrollment",H12*I$4/H$4,IF($E12="Tuition Index",H12*I$5/H$5,IF($E12="% of Salaries",IF($G$6=0,0,$G12/$G$6*I$6),IF($E12="Debt",$G12*Inputs!E$15/12,IF($E12="Reserve Yield",Inputs!E$13*Inputs!E$16,IF($E12="Trend",H12*(1+Inputs!E$12),H12)))))))))))) -> 0 | J12: =IF($E12="Manual",N12,IF($E12="Flat",I12,IF($E12="Inflation",I12*(1+Inputs!F$12),IF($E12="Salary",I12*(1+Inputs!F$10),IF($E12="Benefits",I12*(1+Inputs!F$11),IF($E12="Per Student",I12*J$4/I$4*(1+Inputs!F$12),IF($E12="Enrollment",I12*J$4/I$4,IF($E12="Tuition Index",I12*J$5/I$5,IF($E12="% of Salaries",IF($G$6=0,0,$G12/$G$6*J$6),IF($E12="Debt",$G12*Inputs!F$15/12,IF($E12="Reserve Yield",Inputs!F$13*Inputs!F$16,IF($E12="Trend",I12*(1+Inputs!F$12),I12)))))))))))) -> 0 | K12: =IF($E12="Manual",O12,IF($E12="Flat",J12,IF($E12="Inflation",J12*(1+Inputs!G$12),IF($E12="Salary",J12*(1+Inputs!G$10),IF($E12="Benefits",J12*(1+Inputs!G$11),IF($E12="Per Student",J12*K$4/J$4*(1+Inputs!G$12),IF($E12="Enrollment",J12*K$4/J$4,IF($E12="Tuition Index",J12*K$5/J$5,IF($E12="% of Salaries",IF($G$6=0,0,$G12/$G$6*K$6),IF($E12="Debt",$G12*Inputs!G$15/12,IF($E12="Reserve Yield",Inputs!G$13*Inputs!G$16,IF($E12="Trend",J12*(1+Inputs!G$12),J12)))))))))))) -> 0 | L12: 0 | M12: 0 | N12: 0 | O12: 0
A13: Revenue | B13: 1 Tuition and Fees | C13: 400181 | D13: 400181 Enrollment Fees | E13: Enrollment | F13: Jul Lump | G13: =SUMIFS('QB Import'!$B$1:$B$600,'QB Import'!$H$1:$H$600,$C13,'QB Import'!$G$1:$G$600,1) -> 162300 | H13: =IF($E13="Manual",L13,IF($E13="Flat",G13,IF($E13="Inflation",G13*(1+Inputs!D$12),IF($E13="Salary",G13*(1+Inputs!D$10),IF($E13="Benefits",G13*(1+Inputs!D$11),IF($E13="Per Student",G13*H$4/G$4*(1+Inputs!D$12),IF($E13="Enrollment",G13*H$4/G$4,IF($E13="Tuition Index",G13*H$5/G$5,IF($E13="% of Salaries",IF($G$6=0,0,$G13/$G$6*H$6),IF($E13="Debt",$G13*Inputs!D$15/12,IF($E13="Reserve Yield",Inputs!D$13*Inputs!D$16,IF($E13="Trend",IF(ISNUMBER(Trend!$Q52),Trend!$Q52,G13),G13)))))))))))) -> 164809.79 | I13: =IF($E13="Manual",M13,IF($E13="Flat",H13,IF($E13="Inflation",H13*(1+Inputs!E$12),IF($E13="Salary",H13*(1+Inputs!E$10),IF($E13="Benefits",H13*(1+Inputs!E$11),IF($E13="Per Student",H13*I$4/H$4*(1+Inputs!E$12),IF($E13="Enrollment",H13*I$4/H$4,IF($E13="Tuition Index",H13*I$5/H$5,IF($E13="% of Salaries",IF($G$6=0,0,$G13/$G$6*I$6),IF($E13="Debt",$G13*Inputs!E$15/12,IF($E13="Reserve Yield",Inputs!E$13*Inputs!E$16,IF($E13="Trend",H13*(1+Inputs!E$12),H13)))))))))))) -> 163973.2 | J13: =IF($E13="Manual",N13,IF($E13="Flat",I13,IF($E13="Inflation",I13*(1+Inputs!F$12),IF($E13="Salary",I13*(1+Inputs!F$10),IF($E13="Benefits",I13*(1+Inputs!F$11),IF($E13="Per Student",I13*J$4/I$4*(1+Inputs!F$12),IF($E13="Enrollment",I13*J$4/I$4,IF($E13="Tuition Index",I13*J$5/I$5,IF($E13="% of Salaries",IF($G$6=0,0,$G13/$G$6*J$6),IF($E13="Debt",$G13*Inputs!F$15/12,IF($E13="Reserve Yield",Inputs!F$13*Inputs!F$16,IF($E13="Trend",I13*(1+Inputs!F$12),I13)))))))))))) -> 162578.87 | K13: =IF($E13="Manual",O13,IF($E13="Flat",J13,IF($E13="Inflation",J13*(1+Inputs!G$12),IF($E13="Salary",J13*(1+Inputs!G$10),IF($E13="Benefits",J13*(1+Inputs!G$11),IF($E13="Per Student",J13*K$4/J$4*(1+Inputs!G$12),IF($E13="Enrollment",J13*K$4/J$4,IF($E13="Tuition Index",J13*K$5/J$5,IF($E13="% of Salaries",IF($G$6=0,0,$G13/$G$6*K$6),IF($E13="Debt",$G13*Inputs!G$15/12,IF($E13="Reserve Yield",Inputs!G$13*Inputs!G$16,IF($E13="Trend",J13*(1+Inputs!G$12),J13)))))))))))) -> 161463.4
A14: Revenue | B14: 1 Tuition and Fees | C14: 400183 | D14: 400183 Tuition Insurance Income | E14: Enrollment | F14: Tuition Plan | G14: =SUMIFS('QB Import'!$B$1:$B$600,'QB Import'!$H$1:$H$600,$C14,'QB Import'!$G$1:$G$600,1) -> 139000 | H14: =IF($E14="Manual",L14,IF($E14="Flat",G14,IF($E14="Inflation",G14*(1+Inputs!D$12),IF($E14="Salary",G14*(1+Inputs!D$10),IF($E14="Benefits",G14*(1+Inputs!D$11),IF($E14="Per Student",G14*H$4/G$4*(1+Inputs!D$12),IF($E14="Enrollment",G14*H$4/G$4,IF($E14="Tuition Index",G14*H$5/G$5,IF($E14="% of Salaries",IF($G$6=0,0,$G14/$G$6*H$6),IF($E14="Debt",$G14*Inputs!D$15/12,IF($E14="Reserve Yield",Inputs!D$13*Inputs!D$16,IF($E14="Trend",IF(ISNUMBER(Trend!$Q53),Trend!$Q53,G14),G14)))))))))))) -> 141149.48 | I14: =IF($E14="Manual",M14,IF($E14="Flat",H14,IF($E14="Inflation",H14*(1+Inputs!E$12),IF($E14="Salary",H14*(1+Inputs!E$10),IF($E14="Benefits",H14*(1+Inputs!E$11),IF($E14="Per Student",H14*I$4/H$4*(1+Inputs!E$12),IF($E14="Enrollment",H14*I$4/H$4,IF($E14="Tuition Index",H14*I$5/H$5,IF($E14="% of Salaries",IF($G$6=0,0,$G14/$G$6*I$6),IF($E14="Debt",$G14*Inputs!E$15/12,IF($E14="Reserve Yield",Inputs!E$13*Inputs!E$16,IF($E14="Trend",H14*(1+Inputs!E$12),H14)))))))))))) -> 140432.99 | J14: =IF($E14="Manual",N14,IF($E14="Flat",I14,IF($E14="Inflation",I14*(1+Inputs!F$12),IF($E14="Salary",I14*(1+Inputs!F$10),IF($E14="Benefits",I14*(1+Inputs!F$11),IF($E14="Per Student",I14*J$4/I$4*(1+Inputs!F$12),IF($E14="Enrollment",I14*J$4/I$4,IF($E14="Tuition Index",I14*J$5/I$5,IF($E14="% of Salaries",IF($G$6=0,0,$G14/$G$6*J$6),IF($E14="Debt",$G14*Inputs!F$15/12,IF($E14="Reserve Yield",Inputs!F$13*Inputs!F$16,IF($E14="Trend",I14*(1+Inputs!F$12),I14)))))))))))) -> 139238.83 | K14: =IF($E14="Manual",O14,IF($E14="Flat",J14,IF($E14="Inflation",J14*(1+Inputs!G$12),IF($E14="Salary",J14*(1+Inputs!G$10),IF($E14="Benefits",J14*(1+Inputs!G$11),IF($E14="Per Student",J14*K$4/J$4*(1+Inputs!G$12),IF($E14="Enrollment",J14*K$4/J$4,IF($E14="Tuition Index",J14*K$5/J$5,IF($E14="% of Salaries",IF($G$6=0,0,$G14/$G$6*K$6),IF($E14="Debt",$G14*Inputs!G$15/12,IF($E14="Reserve Yield",Inputs!G$13*Inputs!G$16,IF($E14="Trend",J14*(1+Inputs!G$12),J14)))))))))))) -> 138283.51
A15: Revenue | B15: 1 Tuition and Fees | C15: 400184 | D15: 400184 Application Fees | E15: Flat | F15: Jul Lump | G15: =SUMIFS('QB Import'!$B$1:$B$600,'QB Import'!$H$1:$H$600,$C15,'QB Import'!$G$1:$G$600,1) -> 0 | H15: =IF($E15="Manual",L15,IF($E15="Flat",G15,IF($E15="Inflation",G15*(1+Inputs!D$12),IF($E15="Salary",G15*(1+Inputs!D$10),IF($E15="Benefits",G15*(1+Inputs!D$11),IF($E15="Per Student",G15*H$4/G$4*(1+Inputs!D$12),IF($E15="Enrollment",G15*H$4/G$4,IF($E15="Tuition Index",G15*H$5/G$5,IF($E15="% of Salaries",IF($G$6=0,0,$G15/$G$6*H$6),IF($E15="Debt",$G15*Inputs!D$15/12,IF($E15="Reserve Yield",Inputs!D$13*Inputs!D$16,IF($E15="Trend",IF(ISNUMBER(Trend!$Q54),Trend!$Q54,G15),G15)))))))))))) -> 0 | I15: =IF($E15="Manual",M15,IF($E15="Flat",H15,IF($E15="Inflation",H15*(1+Inputs!E$12),IF($E15="Salary",H15*(1+Inputs!E$10),IF($E15="Benefits",H15*(1+Inputs!E$11),IF($E15="Per Student",H15*I$4/H$4*(1+Inputs!E$12),IF($E15="Enrollment",H15*I$4/H$4,IF($E15="Tuition Index",H15*I$5/H$5,IF($E15="% of Salaries",IF($G$6=0,0,$G15/$G$6*I$6),IF($E15="Debt",$G15*Inputs!E$15/12,IF($E15="Reserve Yield",Inputs!E$13*Inputs!E$16,IF($E15="Trend",H15*(1+Inputs!E$12),H15)))))))))))) -> 0 | J15: =IF($E15="Manual",N15,IF($E15="Flat",I15,IF($E15="Inflation",I15*(1+Inputs!F$12),IF($E15="Salary",I15*(1+Inputs!F$10),IF($E15="Benefits",I15*(1+Inputs!F$11),IF($E15="Per Student",I15*J$4/I$4*(1+Inputs!F$12),IF($E15="Enrollment",I15*J$4/I$4,IF($E15="Tuition Index",I15*J$5/I$5,IF($E15="% of Salaries",IF($G$6=0,0,$G15/$G$6*J$6),IF($E15="Debt",$G15*Inputs!F$15/12,IF($E15="Reserve Yield",Inputs!F$13*Inputs!F$16,IF($E15="Trend",I15*(1+Inputs!F$12),I15)))))))))))) -> 0 | K15: =IF($E15="Manual",O15,IF($E15="Flat",J15,IF($E15="Inflation",J15*(1+Inputs!G$12),IF($E15="Salary",J15*(1+Inputs!G$10),IF($E15="Benefits",J15*(1+Inputs!G$11),IF($E15="Per Student",J15*K$4/J$4*(1+Inputs!G$12),IF($E15="Enrollment",J15*K$4/J$4,IF($E15="Tuition Index",J15*K$5/J$5,IF($E15="% of Salaries",IF($G$6=0,0,$G15/$G$6*K$6),IF($E15="Debt",$G15*Inputs!G$15/12,IF($E15="Reserve Yield",Inputs!G$13*Inputs!G$16,IF($E15="Trend",J15*(1+Inputs!G$12),J15)))))))))))) -> 0
A16: Revenue | B16: 1 Tuition and Fees | C16: 400185 | D16: 400185 Enrollment Fee Waived - Alumni Credit | E16: Flat | F16: Jul Lump | G16: =SUMIFS('QB Import'!$B$1:$B$600,'QB Import'!$H$1:$H$600,$C16,'QB Import'!$G$1:$G$600,1) -> 0 | H16: =IF($E16="Manual",L16,IF($E16="Flat",G16,IF($E16="Inflation",G16*(1+Inputs!D$12),IF($E16="Salary",G16*(1+Inputs!D$10),IF($E16="Benefits",G16*(1+Inputs!D$11),IF($E16="Per Student",G16*H$4/G$4*(1+Inputs!D$12),IF($E16="Enrollment",G16*H$4/G$4,IF($E16="Tuition Index",G16*H$5/G$5,IF($E16="% of Salaries",IF($G$6=0,0,$G16/$G$6*H$6),IF($E16="Debt",$G16*Inputs!D$15/12,IF($E16="Reserve Yield",Inputs!D$13*Inputs!D$16,IF($E16="Trend",IF(ISNUMBER(Trend!$Q55),Trend!$Q55,G16),G16)))))))))))) -> 0 | I16: =IF($E16="Manual",M16,IF($E16="Flat",H16,IF($E16="Inflation",H16*(1+Inputs!E$12),IF($E16="Salary",H16*(1+Inputs!E$10),IF($E16="Benefits",H16*(1+Inputs!E$11),IF($E16="Per Student",H16*I$4/H$4*(1+Inputs!E$12),IF($E16="Enrollment",H16*I$4/H$4,IF($E16="Tuition Index",H16*I$5/H$5,IF($E16="% of Salaries",IF($G$6=0,0,$G16/$G$6*I$6),IF($E16="Debt",$G16*Inputs!E$15/12,IF($E16="Reserve Yield",Inputs!E$13*Inputs!E$16,IF($E16="Trend",H16*(1+Inputs!E$12),H16)))))))))))) -> 0 | J16: =IF($E16="Manual",N16,IF($E16="Flat",I16,IF($E16="Inflation",I16*(1+Inputs!F$12),IF($E16="Salary",I16*(1+Inputs!F$10),IF($E16="Benefits",I16*(1+Inputs!F$11),IF($E16="Per Student",I16*J$4/I$4*(1+Inputs!F$12),IF($E16="Enrollment",I16*J$4/I$4,IF($E16="Tuition Index",I16*J$5/I$5,IF($E16="% of Salaries",IF($G$6=0,0,$G16/$G$6*J$6),IF($E16="Debt",$G16*Inputs!F$15/12,IF($E16="Reserve Yield",Inputs!F$13*Inputs!F$16,IF($E16="Trend",I16*(1+Inputs!F$12),I16)))))))))))) -> 0 | K16: =IF($E16="Manual",O16,IF($E16="Flat",J16,IF($E16="Inflation",J16*(1+Inputs!G$12),IF($E16="Salary",J16*(1+Inputs!G$10),IF($E16="Benefits",J16*(1+Inputs!G$11),IF($E16="Per Student",J16*K$4/J$4*(1+Inputs!G$12),IF($E16="Enrollment",J16*K$4/J$4,IF($E16="Tuition Index",J16*K$5/J$5,IF($E16="% of Salaries",IF($G$6=0,0,$G16/$G$6*K$6),IF($E16="Debt",$G16*Inputs!G$15/12,IF($E16="Reserve Yield",Inputs!G$13*Inputs!G$16,IF($E16="Trend",J16*(1+Inputs!G$12),J16)))))))))))) -> 0
A17: Revenue | B17: 1 Tuition and Fees | C17: 400199 | D17: 400199 Fee - Tuition Discount | E17: Flat | F17: Jul Lump | G17: =SUMIFS('QB Import'!$B$1:$B$600,'QB Import'!$H$1:$H$600,$C17,'QB Import'!$G$1:$G$600,1) -> 0 | H17: =IF($E17="Manual",L17,IF($E17="Flat",G17,IF($E17="Inflation",G17*(1+Inputs!D$12),IF($E17="Salary",G17*(1+Inputs!D$10),IF($E17="Benefits",G17*(1+Inputs!D$11),IF($E17="Per Student",G17*H$4/G$4*(1+Inputs!D$12),IF($E17="Enrollment",G17*H$4/G$4,IF($E17="Tuition Index",G17*H$5/G$5,IF($E17="% of Salaries",IF($G$6=0,0,$G17/$G$6*H$6),IF($E17="Debt",$G17*Inputs!D$15/12,IF($E17="Reserve Yield",Inputs!D$13*Inputs!D$16,IF($E17="Trend",IF(ISNUMBER(Trend!$Q56),Trend!$Q56,G17),G17)))))))))))) -> 0 | I17: =IF($E17="Manual",M17,IF($E17="Flat",H17,IF($E17="Inflation",H17*(1+Inputs!E$12),IF($E17="Salary",H17*(1+Inputs!E$10),IF($E17="Benefits",H17*(1+Inputs!E$11),IF($E17="Per Student",H17*I$4/H$4*(1+Inputs!E$12),IF($E17="Enrollment",H17*I$4/H$4,IF($E17="Tuition Index",H17*I$5/H$5,IF($E17="% of Salaries",IF($G$6=0,0,$G17/$G$6*I$6),IF($E17="Debt",$G17*Inputs!E$15/12,IF($E17="Reserve Yield",Inputs!E$13*Inputs!E$16,IF($E17="Trend",H17*(1+Inputs!E$12),H17)))))))))))) -> 0 | J17: =IF($E17="Manual",N17,IF($E17="Flat",I17,IF($E17="Inflation",I17*(1+Inputs!F$12),IF($E17="Salary",I17*(1+Inputs!F$10),IF($E17="Benefits",I17*(1+Inputs!F$11),IF($E17="Per Student",I17*J$4/I$4*(1+Inputs!F$12),IF($E17="Enrollment",I17*J$4/I$4,IF($E17="Tuition Index",I17*J$5/I$5,IF($E17="% of Salaries",IF($G$6=0,0,$G17/$G$6*J$6),IF($E17="Debt",$G17*Inputs!F$15/12,IF($E17="Reserve Yield",Inputs!F$13*Inputs!F$16,IF($E17="Trend",I17*(1+Inputs!F$12),I17)))))))))))) -> 0 | K17: =IF($E17="Manual",O17,IF($E17="Flat",J17,IF($E17="Inflation",J17*(1+Inputs!G$12),IF($E17="Salary",J17*(1+Inputs!G$10),IF($E17="Benefits",J17*(1+Inputs!G$11),IF($E17="Per Student",J17*K$4/J$4*(1+Inputs!G$12),IF($E17="Enrollment",J17*K$4/J$4,IF($E17="Tuition Index",J17*K$5/J$5,IF($E17="% of Salaries",IF($G$6=0,0,$G17/$G$6*K$6),IF($E17="Debt",$G17*Inputs!G$15/12,IF($E17="Reserve Yield",Inputs!G$13*Inputs!G$16,IF($E17="Trend",J17*(1+Inputs!G$12),J17)))))))))))) -> 0
A18: Revenue | B18: 1 Tuition and Fees | C18: 400201 | D18: 400201 Referral Fee - Tuition Discount | E18: Flat | F18: Jul Lump | G18: =SUMIFS('QB Import'!$B$1:$B$600,'QB Import'!$H$1:$H$600,$C18,'QB Import'!$G$1:$G$600,1) -> 0 | H18: =IF($E18="Manual",L18,IF($E18="Flat",G18,IF($E18="Inflation",G18*(1+Inputs!D$12),IF($E18="Salary",G18*(1+Inputs!D$10),IF($E18="Benefits",G18*(1+Inputs!D$11),IF($E18="Per Student",G18*H$4/G$4*(1+Inputs!D$12),IF($E18="Enrollment",G18*H$4/G$4,IF($E18="Tuition Index",G18*H$5/G$5,IF($E18="% of Salaries",IF($G$6=0,0,$G18/$G$6*H$6),IF($E18="Debt",$G18*Inputs!D$15/12,IF($E18="Reserve Yield",Inputs!D$13*Inputs!D$16,IF($E18="Trend",IF(ISNUMBER(Trend!$Q57),Trend!$Q57,G18),G18)))))))))))) -> 0 | I18: =IF($E18="Manual",M18,IF($E18="Flat",H18,IF($E18="Inflation",H18*(1+Inputs!E$12),IF($E18="Salary",H18*(1+Inputs!E$10),IF($E18="Benefits",H18*(1+Inputs!E$11),IF($E18="Per Student",H18*I$4/H$4*(1+Inputs!E$12),IF($E18="Enrollment",H18*I$4/H$4,IF($E18="Tuition Index",H18*I$5/H$5,IF($E18="% of Salaries",IF($G$6=0,0,$G18/$G$6*I$6),IF($E18="Debt",$G18*Inputs!E$15/12,IF($E18="Reserve Yield",Inputs!E$13*Inputs!E$16,IF($E18="Trend",H18*(1+Inputs!E$12),H18)))))))))))) -> 0 | J18: =IF($E18="Manual",N18,IF($E18="Flat",I18,IF($E18="Inflation",I18*(1+Inputs!F$12),IF($E18="Salary",I18*(1+Inputs!F$10),IF($E18="Benefits",I18*(1+Inputs!F$11),IF($E18="Per Student",I18*J$4/I$4*(1+Inputs!F$12),IF($E18="Enrollment",I18*J$4/I$4,IF($E18="Tuition Index",I18*J$5/I$5,IF($E18="% of Salaries",IF($G$6=0,0,$G18/$G$6*J$6),IF($E18="Debt",$G18*Inputs!F$15/12,IF($E18="Reserve Yield",Inputs!F$13*Inputs!F$16,IF($E18="Trend",I18*(1+Inputs!F$12),I18)))))))))))) -> 0 | K18: =IF($E18="Manual",O18,IF($E18="Flat",J18,IF($E18="Inflation",J18*(1+Inputs!G$12),IF($E18="Salary",J18*(1+Inputs!G$10),IF($E18="Benefits",J18*(1+Inputs!G$11),IF($E18="Per Student",J18*K$4/J$4*(1+Inputs!G$12),IF($E18="Enrollment",J18*K$4/J$4,IF($E18="Tuition Index",J18*K$5/J$5,IF($E18="% of Salaries",IF($G$6=0,0,$G18/$G$6*K$6),IF($E18="Debt",$G18*Inputs!G$15/12,IF($E18="Reserve Yield",Inputs!G$13*Inputs!G$16,IF($E18="Trend",J18*(1+Inputs!G$12),J18)))))))))))) -> 0
A19: Revenue | B19: 1 Tuition and Fees | C19: 400126 | D19: 400126 Late Fees | E19: Manual | F19: Even | G19: =SUMIFS('QB Import'!$B$1:$B$600,'QB Import'!$H$1:$H$600,$C19,'QB Import'!$G$1:$G$600,1) -> 9300 | H19: =IF($E19="Manual",L19,IF($E19="Flat",G19,IF($E19="Inflation",G19*(1+Inputs!D$12),IF($E19="Salary",G19*(1+Inputs!D$10),IF($E19="Benefits",G19*(1+Inputs!D$11),IF($E19="Per Student",G19*H$4/G$4*(1+Inputs!D$12),IF($E19="Enrollment",G19*H$4/G$4,IF($E19="Tuition Index",G19*H$5/G$5,IF($E19="% of Salaries",IF($G$6=0,0,$G19/$G$6*H$6),IF($E19="Debt",$G19*Inputs!D$15/12,IF($E19="Reserve Yield",Inputs!D$13*Inputs!D$16,IF($E19="Trend",IF(ISNUMBER(Trend!$Q58),Trend!$Q58,G19),G19)))))))))))) -> 3000 | I19: =IF($E19="Manual",M19,IF($E19="Flat",H19,IF($E19="Inflation",H19*(1+Inputs!E$12),IF($E19="Salary",H19*(1+Inputs!E$10),IF($E19="Benefits",H19*(1+Inputs!E$11),IF($E19="Per Student",H19*I$4/H$4*(1+Inputs!E$12),IF($E19="Enrollment",H19*I$4/H$4,IF($E19="Tuition Index",H19*I$5/H$5,IF($E19="% of Salaries",IF($G$6=0,0,$G19/$G$6*I$6),IF($E19="Debt",$G19*Inputs!E$15/12,IF($E19="Reserve Yield",Inputs!E$13*Inputs!E$16,IF($E19="Trend",H19*(1+Inputs!E$12),H19)))))))))))) -> 3000 | J19: =IF($E19="Manual",N19,IF($E19="Flat",I19,IF($E19="Inflation",I19*(1+Inputs!F$12),IF($E19="Salary",I19*(1+Inputs!F$10),IF($E19="Benefits",I19*(1+Inputs!F$11),IF($E19="Per Student",I19*J$4/I$4*(1+Inputs!F$12),IF($E19="Enrollment",I19*J$4/I$4,IF($E19="Tuition Index",I19*J$5/I$5,IF($E19="% of Salaries",IF($G$6=0,0,$G19/$G$6*J$6),IF($E19="Debt",$G19*Inputs!F$15/12,IF($E19="Reserve Yield",Inputs!F$13*Inputs!F$16,IF($E19="Trend",I19*(1+Inputs!F$12),I19)))))))))))) -> 3000 | K19: =IF($E19="Manual",O19,IF($E19="Flat",J19,IF($E19="Inflation",J19*(1+Inputs!G$12),IF($E19="Salary",J19*(1+Inputs!G$10),IF($E19="Benefits",J19*(1+Inputs!G$11),IF($E19="Per Student",J19*K$4/J$4*(1+Inputs!G$12),IF($E19="Enrollment",J19*K$4/J$4,IF($E19="Tuition Index",J19*K$5/J$5,IF($E19="% of Salaries",IF($G$6=0,0,$G19/$G$6*K$6),IF($E19="Debt",$G19*Inputs!G$15/12,IF($E19="Reserve Yield",Inputs!G$13*Inputs!G$16,IF($E19="Trend",J19*(1+Inputs!G$12),J19)))))))))))) -> 3000 | L19: 3000 | M19: 3000 | N19: 3000 | O19: 3000
A20: Revenue | B20: 1 Tuition and Fees | C20: 400127 | D20: 400127 Waived Late Fees | E20: Flat | F20: Even | G20: =SUMIFS('QB Import'!$B$1:$B$600,'QB Import'!$H$1:$H$600,$C20,'QB Import'!$G$1:$G$600,1) -> 0 | H20: =IF($E20="Manual",L20,IF($E20="Flat",G20,IF($E20="Inflation",G20*(1+Inputs!D$12),IF($E20="Salary",G20*(1+Inputs!D$10),IF($E20="Benefits",G20*(1+Inputs!D$11),IF($E20="Per Student",G20*H$4/G$4*(1+Inputs!D$12),IF($E20="Enrollment",G20*H$4/G$4,IF($E20="Tuition Index",G20*H$5/G$5,IF($E20="% of Salaries",IF($G$6=0,0,$G20/$G$6*H$6),IF($E20="Debt",$G20*Inputs!D$15/12,IF($E20="Reserve Yield",Inputs!D$13*Inputs!D$16,IF($E20="Trend",IF(ISNUMBER(Trend!$Q59),Trend!$Q59,G20),G20)))))))))))) -> 0 | I20: =IF($E20="Manual",M20,IF($E20="Flat",H20,IF($E20="Inflation",H20*(1+Inputs!E$12),IF($E20="Salary",H20*(1+Inputs!E$10),IF($E20="Benefits",H20*(1+Inputs!E$11),IF($E20="Per Student",H20*I$4/H$4*(1+Inputs!E$12),IF($E20="Enrollment",H20*I$4/H$4,IF($E20="Tuition Index",H20*I$5/H$5,IF($E20="% of Salaries",IF($G$6=0,0,$G20/$G$6*I$6),IF($E20="Debt",$G20*Inputs!E$15/12,IF($E20="Reserve Yield",Inputs!E$13*Inputs!E$16,IF($E20="Trend",H20*(1+Inputs!E$12),H20)))))))))))) -> 0 | J20: =IF($E20="Manual",N20,IF($E20="Flat",I20,IF($E20="Inflation",I20*(1+Inputs!F$12),IF($E20="Salary",I20*(1+Inputs!F$10),IF($E20="Benefits",I20*(1+Inputs!F$11),IF($E20="Per Student",I20*J$4/I$4*(1+Inputs!F$12),IF($E20="Enrollment",I20*J$4/I$4,IF($E20="Tuition Index",I20*J$5/I$5,IF($E20="% of Salaries",IF($G$6=0,0,$G20/$G$6*J$6),IF($E20="Debt",$G20*Inputs!F$15/12,IF($E20="Reserve Yield",Inputs!F$13*Inputs!F$16,IF($E20="Trend",I20*(1+Inputs!F$12),I20)))))))))))) -> 0 | K20: =IF($E20="Manual",O20,IF($E20="Flat",J20,IF($E20="Inflation",J20*(1+Inputs!G$12),IF($E20="Salary",J20*(1+Inputs!G$10),IF($E20="Benefits",J20*(1+Inputs!G$11),IF($E20="Per Student",J20*K$4/J$4*(1+Inputs!G$12),IF($E20="Enrollment",J20*K$4/J$4,IF($E20="Tuition Index",J20*K$5/J$5,IF($E20="% of Salaries",IF($G$6=0,0,$G20/$G$6*K$6),IF($E20="Debt",$G20*Inputs!G$15/12,IF($E20="Reserve Yield",Inputs!G$13*Inputs!G$16,IF($E20="Trend",J20*(1+Inputs!G$12),J20)))))))))))) -> 0
A21: Revenue | B21: 1 Tuition and Fees | C21: 400128 | D21: 400128 Late Fees - Past Due Accounts | E21: Flat | F21: Even | G21: =SUMIFS('QB Import'!$B$1:$B$600,'QB Import'!$H$1:$H$600,$C21,'QB Import'!$G$1:$G$600,1) -> 0 | H21: =IF($E21="Manual",L21,IF($E21="Flat",G21,IF($E21="Inflation",G21*(1+Inputs!D$12),IF($E21="Salary",G21*(1+Inputs!D$10),IF($E21="Benefits",G21*(1+Inputs!D$11),IF($E21="Per Student",G21*H$4/G$4*(1+Inputs!D$12),IF($E21="Enrollment",G21*H$4/G$4,IF($E21="Tuition Index",G21*H$5/G$5,IF($E21="% of Salaries",IF($G$6=0,0,$G21/$G$6*H$6),IF($E21="Debt",$G21*Inputs!D$15/12,IF($E21="Reserve Yield",Inputs!D$13*Inputs!D$16,IF($E21="Trend",IF(ISNUMBER(Trend!$Q60),Trend!$Q60,G21),G21)))))))))))) -> 0 | I21: =IF($E21="Manual",M21,IF($E21="Flat",H21,IF($E21="Inflation",H21*(1+Inputs!E$12),IF($E21="Salary",H21*(1+Inputs!E$10),IF($E21="Benefits",H21*(1+Inputs!E$11),IF($E21="Per Student",H21*I$4/H$4*(1+Inputs!E$12),IF($E21="Enrollment",H21*I$4/H$4,IF($E21="Tuition Index",H21*I$5/H$5,IF($E21="% of Salaries",IF($G$6=0,0,$G21/$G$6*I$6),IF($E21="Debt",$G21*Inputs!E$15/12,IF($E21="Reserve Yield",Inputs!E$13*Inputs!E$16,IF($E21="Trend",H21*(1+Inputs!E$12),H21)))))))))))) -> 0 | J21: =IF($E21="Manual",N21,IF($E21="Flat",I21,IF($E21="Inflation",I21*(1+Inputs!F$12),IF($E21="Salary",I21*(1+Inputs!F$10),IF($E21="Benefits",I21*(1+Inputs!F$11),IF($E21="Per Student",I21*J$4/I$4*(1+Inputs!F$12),IF($E21="Enrollment",I21*J$4/I$4,IF($E21="Tuition Index",I21*J$5/I$5,IF($E21="% of Salaries",IF($G$6=0,0,$G21/$G$6*J$6),IF($E21="Debt",$G21*Inputs!F$15/12,IF($E21="Reserve Yield",Inputs!F$13*Inputs!F$16,IF($E21="Trend",I21*(1+Inputs!F$12),I21)))))))))))) -> 0 | K21: =IF($E21="Manual",O21,IF($E21="Flat",J21,IF($E21="Inflation",J21*(1+Inputs!G$12),IF($E21="Salary",J21*(1+Inputs!G$10),IF($E21="Benefits",J21*(1+Inputs!G$11),IF($E21="Per Student",J21*K$4/J$4*(1+Inputs!G$12),IF($E21="Enrollment",J21*K$4/J$4,IF($E21="Tuition Index",J21*K$5/J$5,IF($E21="% of Salaries",IF($G$6=0,0,$G21/$G$6*K$6),IF($E21="Debt",$G21*Inputs!G$15/12,IF($E21="Reserve Yield",Inputs!G$13*Inputs!G$16,IF($E21="Trend",J21*(1+Inputs!G$12),J21)))))))))))) -> 0
